Workbook

Sheet Instructions
B2: Suivi de vérification fonctionnelle des blocs
B3: Programmation micro:bit V2 — interface Blockly
B6: Objectif
B7: Vérifier, bloc par bloc, que chaque bloc créé pour ce projet fonctionne réellement — aussi bien dans le simulateur du navigateur que sur une vraie carte micro:bit (avec le module Grove ou le robot correspondant si besoin).
B9: Contenu
B10: L'onglet "Blocs" liste les 115 blocs créés pour ce projet, variante sans robots (Maqueen Plus, Maqueen Lite, Kitrobot v2 et LiDAR retirés) (catégorie, sous-catégorie, libellé tel qu'affiché dans la boîte à outils, et identifiant technique interne). Les blocs standards de Blockly (Logique, Boucles natives, Texte, Maths de base, Variables, Fonctions) ne sont pas listés : ce ne sont pas des blocs créés pour ce projet.
B12: Comment remplir
B13: Pour chaque bloc, choisir une valeur dans les colonnes "Fonctionne en simulateur" et "Fonctionne sur carte réelle" (menu déroulant : À tester / Oui / Non / Partiel), puis renseigner la date, la personne qui a testé, et une remarque en cas de problème (comportement observé, message d'erreur, condition qui déclenche le bug...).
B15: Onglet Résumé
B16: Calcule automatiquement, pour chaque catégorie, le nombre de blocs, le nombre déjà testé et le nombre fonctionnel — se met à jour tout seul au fur et à mesure du remplissage de l'onglet "Blocs".
B19: Exemple de ligne remplie (onglet "Blocs", à titre d'illustration) :
B20: Catégorie | C20: Sous-catégorie | D20: Bloc | E20: Identifiant technique | F20: Fonctionne en simulateur | G20: Fonctionne sur carte réelle | H20: Date du test | I20: Testé par | J20: Remarques
B21: Temps | D21: attendre | E21: attendre_temps | F21: Oui | G21: Oui | H21: 2026-09-24 | I21: J. Reynald | J21: RAS, testé avec des délais de 100 ms à 5 s

Sheet Blocs
A1: Catégorie | B1: Sous-catégorie | C1: Bloc | D1: Identifiant technique | E1: Fonctionne en simulateur | F1: Fonctionne sur carte réelle | G1: Date du test | H1: Testé par | I1: Remarques
A2: Temps | C2: attendre | D2: attendre_temps | E2: Oui | F2: Oui | H2: moi
A3: Temps | C3: attendre jusqu'à | D3: attendre_jusqua | E3: Partiel | F3: Oui | I3: Simulateur : la boucle d'attente ne peut pas voir la condition changer pendant un tour ; le tour est ignoré sans erreur (PIÈGE nº54). A re-tester en simulation continue (appuyer pendant l'exécution). Carte réelle : inchangé, sleep() réellement bloquant.
A4: Temps | C4: répéter toutes les ... h ... min ... s | D4: repeter_toutes_les | E4: Oui | F4: Oui
A5: Temps | C5: remettre le chronomètre à 0 | D5: reset_chrono | E5: À tester | F5: Oui | I5: running_time() était figée à 0 dans le simulateur (valeur du chronomètre toujours 0). Corrigé depuis (PIÈGE nº55) : à re-tester.
A6: Temps | C6: valeur du chronomètre en | D6: valeur_chrono | E6: À tester | F6: Oui | I6: Même cause que reset_chrono (running_time() figée à 0 en simulation, corrigée : PIÈGE nº55). A re-tester : la valeur doit avancer avec le temps et repartir de 0 après Réinitialiser.
A7: Affichage | C7: afficher | D7: afficher_valeur | E7: Oui | F7: Oui
A8: Affichage | C8: faire défiler | D8: faire_defiler | E8: Oui | F8: Oui
A9: Affichage | C9: afficher l'icône | D9: afficher_icone | E9: Oui | F9: Oui
A10: Affichage | C10: afficher l'image | D10: afficher_image_matrice | E10: Oui | F10: Oui
A11: Affichage | C11: effacer l'écran | D11: effacer_ecran | E11: Oui | F11: Oui
A12: Entrées/Sorties | C12: si le bouton ... est appuyé alors | D12: si_bouton_appuye | E12: Oui | F12: Oui
A13: Entrées/Sorties | C13: si LOGO est touché alors | D13: si_logo_touche | E13: Oui | F13: Oui
A14: Entrées/Sorties | C14: si secoué alors | D14: si_secoue_alors | E14: Oui | F14: Oui
A15: Entrées/Sorties | C15: bouton ... est appuyé | D15: bouton_est_appuye | E15: Oui | F15: Oui
A16: Entrées/Sorties | C16: le logo est appuyé | D16: logo_est_touche | E16: Oui | F16: Oui
A17: Entrées/Sorties | C17: nombre de clics du bouton | D17: nombre_clics_bouton | E17: À tester | F17: À tester | I17: Code généré modifié (compteur cumulatif _lire_clics_x, PIÈGE nº53) et simulateur à session persistante : à re-tester des deux côtés. Scénario : 10 clics espacés sur B -> icône Cœur.
A18: Entrées/Sorties | C18: [Micro:bit] réinitialiser la carte | D18: reinitialiser_microbit | E18: Oui | F18: Oui
A19: Capteurs | C19: lorsque le bouton ... est pressé | D19: lorsque_bouton | E19: À tester | F19: À tester
A20: Capteurs | C20: lorsque | D20: lorsque_geste | E20: À tester | F20: À tester
A21: Capteurs | C21: lorsque la broche ... est | D21: lorsque_broche | E21: À tester | F21: À tester | I21: Mode tactile capacitif (set_touch_mode) activé automatiquement depuis PIÈGE nº57 : vérifier sur carte V2 qu'un seul doigt sur P0/P1/P2 suffit (sans toucher GND).
A22: Capteurs | C22: lorsque le son ... est detecté | D22: lorsque_son_detecte | E22: À tester | F22: À tester
A23: Capteurs | C23: sur le logo | D23: lorsque_logo | E23: À tester | F23: À tester
A24: Capteurs | C24: accélération (mg) | D24: capteur_acceleration | E24: À tester | F24: À tester
A25: Capteurs | C25: broche ... est pressée | D25: broche_est_pressee | E25: À tester | F25: À tester | I25: Même correctif que lorsque_broche (PIÈGE nº57) : vérifier sur carte V2 qu'un seul doigt suffit.
A26: Capteurs | C26: niveau d'intensité lumineuse | D26: capteur_luminosite | E26: À tester | F26: À tester
A27: Capteurs | C27: direction de la boussole (°) | D27: capteur_boussole_direction | E27: À tester | F27: À tester
A28: Capteurs | C28: température (° C) | D28: capteur_temperature | E28: À tester | F28: À tester
A29: Capteurs | C29: geste ... est actif | D29: geste_est_actif | E29: À tester | F29: À tester
A30: Capteurs | C30: niveau sonore | D30: micro_intensite_son | E30: À tester | F30: À tester
A31: Capteurs | C31: calibrer la boussole | D31: capteur_boussole_calibrer | E31: À tester | F31: À tester
A32: Capteurs | C32: force magnétique (µT) | D32: capteur_boussole_force | E32: À tester | F32: À tester
A33: Capteurs | C33: rotation (°) | D33: capteur_rotation | E33: À tester | F33: À tester
A34: Capteurs | C34: temps d'exécution | D34: temps_execution | E34: À tester | F34: À tester
A35: Capteurs | C35: spécifier la gamme de l'acceleromètre | D35: gamme_accelerometre | E35: À tester | F35: À tester
A36: Capteurs | C36: définit le seuil du son ... à | D36: micro_definir_seuil | E36: À tester | F36: À tester
A37: Actionneurs (Audio) | C37: [Audio] jouer la musique | D37: audio_jouer | E37: À tester | F37: À tester
... A40: Actionneurs (Audio) | C40: [Speech] dire ... vitesse ... hauteur | D40: speech_dire | E40: À tester | F40: À tester
A41: Communication | B41: Groupe | C41: allumer la radio | D41: radio_activer | E41: À tester | F41: À tester
A42: Communication | B42: Groupe | C42: radio : définir le groupe | D42: radio_groupe | E42: À tester | F42: À tester
...

Sheet Résumé
A1: Résumé de la vérification par catégorie
A3: Catégorie | B3: Nombre de blocs | C3: Testés en simulateur | D3: Fonctionnels en simulateur | E3: Testés sur carte réelle | F3: Fonctionnels sur carte réelle
A4: Temps | B4: =COUNTIF(Blocs!$A$2:$A$116,A4) -> 5 | C4: =COUNTIFS(Blocs!$A$2:$A$116,A4,Blocs!$E$2:$E$116,"<>À tester") -> 3 | D4: =COUNTIFS(Blocs!$A$2:$A$116,A4,Blocs!$E$2:$E$116,"Oui") -> 2 | E4: =COUNTIFS(Blocs!$A$2:$A$116,A4,Blocs!$F$2:$F$116,"<>À tester") -> 5 | F4: =COUNTIFS(Blocs!$A$2:$A$116,A4,Blocs!$F$2:$F$116,"Oui") -> 5
A5: Affichage | B5: =COUNTIF(Blocs!$A$2:$A$116,A5) -> 5 | C5: =COUNTIFS(Blocs!$A$2:$A$116,A5,Blocs!$E$2:$E$116,"<>À tester") -> 5 | D5: =COUNTIFS(Blocs!$A$2:$A$116,A5,Blocs!$E$2:$E$116,"Oui") -> 5 | E5: =COUNTIFS(Blocs!$A$2:$A$116,A5,Blocs!$F$2:$F$116,"<>À tester") -> 5 | F5: =COUNTIFS(Blocs!$A$2:$A$116,A5,Blocs!$F$2:$F$116,"Oui") -> 5
A6: Entrées/Sorties | B6: =COUNTIF(Blocs!$A$2:$A$116,A6) -> 7 | C6: =COUNTIFS(Blocs!$A$2:$A$116,A6,Blocs!$E$2:$E$116,"<>À tester") -> 6 | D6: =COUNTIFS(Blocs!$A$2:$A$116,A6,Blocs!$E$2:$E$116,"Oui") -> 6 | E6: =COUNTIFS(Blocs!$A$2:$A$116,A6,Blocs!$F$2:$F$116,"<>À tester") -> 6 | F6: =COUNTIFS(Blocs!$A$2:$A$116,A6,Blocs!$F$2:$F$116,"Oui") -> 6
A7: Capteurs | B7: =COUNTIF(Blocs!$A$2:$A$116,A7) -> 18 | C7: =COUNTIFS(Blocs!$A$2:$A$116,A7,Blocs!$E$2:$E$116,"<>À tester") -> 0 | D7: =COUNTIFS(Blocs!$A$2:$A$116,A7,Blocs!$E$2:$E$116,"Oui") -> 0 | E7: =COUNTIFS(Blocs!$A$2:$A$116,A7,Blocs!$F$2:$F$116,"<>À tester") -> 0 | F7: =COUNTIFS(Blocs!$A$2:$A$116,A7,Blocs!$F$2:$F$116,"Oui") -> 0
A8: Actionneurs (Audio) | B8: =COUNTIF(Blocs!$A$2:$A$116,A8) -> 4 | C8: =COUNTIFS(Blocs!$A$2:$A$116,A8,Blocs!$E$2:$E$116,"<>À tester") -> 0 | D8: =COUNTIFS(Blocs!$A$2:$A$116,A8,Blocs!$E$2:$E$116,"Oui") -> 0 | E8: =COUNTIFS(Blocs!$A$2:$A$116,A8,Blocs!$F$2:$F$116,"<>À tester") -> 0 | F8: =COUNTIFS(Blocs!$A$2:$A$116,A8,Blocs!$F$2:$F$116,"Oui") -> 0
A9: Communication | B9: =COUNTIF(Blocs!$A$2:$A$116,A9) -> 9 | C9: =COUNTIFS(Blocs!$A$2:$A$116,A9,Blocs!$E$2:$E$116,"<>À tester") -> 0 | D9: =COUNTIFS(Blocs!$A$2:$A$116,A9,Blocs!$E$2:$E$116,"Oui") -> 0 | E9: =COUNTIFS(Blocs!$A$2:$A$116,A9,Blocs!$F$2:$F$116,"<>À tester") -> 0 | F9: =COUNTIFS(Blocs!$A$2:$A$116,A9,Blocs!$F$2:$F$116,"Oui") -> 0
A10: Servos | B10: =COUNTIF(Blocs!$A$2:$A$116,A10) -> 6 | C10: =COUNTIFS(Blocs!$A$2:$A$116,A10,Blocs!$E$2:$E$116,"<>À tester") -> 0 | D10: =COUNTIFS(Blocs!$A$2:$A$116,A10,Blocs!$E$2:$E$116,"Oui") -> 0 | E10: =COUNTIFS(Blocs!$A$2:$A$116,A10,Blocs!$F$2:$F$116,"<>À tester") -> 0 | F10: =COUNTIFS(Blocs!$A$2:$A$116,A10,Blocs!$F$2:$F$116,"Oui") -> 0
A11: Grove | B11: =COUNTIF(Blocs!$A$2:$A$116,A11) -> 50 | C11: =COUNTIFS(Blocs!$A$2:$A$116,A11,Blocs!$E$2:$E$116,"<>À tester") -> 4 | D11: =COUNTIFS(Blocs!$A$2:$A$116,A11,Blocs!$E$2:$E$116,"Oui") -> 4 | E11: =COUNTIFS(Blocs!$A$2:$A$116,A11,Blocs!$F$2:$F$116,"<>À tester") -> 4 | F11: =COUNTIFS(Blocs!$A$2:$A$116,A11,Blocs!$F$2:$F$116,"Oui") -> 3
A12: Boucles | B12: =COUNTIF(Blocs!$A$2:$A$116,A12) -> 2 | C12: =COUNTIFS(Blocs!$A$2:$A$116,A12,Blocs!$E$2:$E$116,"<>À tester") -> 0 | D12: =COUNTIFS(Blocs!$A$2:$A$116,A12,Blocs!$E$2:$E$116,"Oui") -> 0 | E12: =COUNTIFS(Blocs!$A$2:$A$116,A12,Blocs!$F$2:$F$116,"<>À tester") -> 0 | F12: =COUNTIFS(Blocs!$A$2:$A$116,A12,Blocs!$F$2:$F$116,"Oui") -> 0
A13: Maths | B13: =COUNTIF(Blocs!$A$2:$A$116,A13) -> 7 | C13: =COUNTIFS(Blocs!$A$2:$A$116,A13,Blocs!$E$2:$E$116,"<>À tester") -> 1 | D13: =COUNTIFS(Blocs!$A$2:$A$116,A13,Blocs!$E$2:$E$116,"Oui") -> 1 | E13: =COUNTIFS(Blocs!$A$2:$A$116,A13,Blocs!$F$2:$F$116,"<>À tester") -> 1 | F13: =COUNTIFS(Blocs!$A$2:$A$116,A13,Blocs!$F$2:$F$116,"Oui") -> 1
A14: Reconstruction | B14: =COUNTIF(Blocs!$A$2:$A$116,A14) -> 2 | C14: =COUNTIFS(Blocs!$A$2:$A$116,A14,Blocs!$E$2:$E$116,"<>À tester") -> 0 | D14: =COUNTIFS(Blocs!$A$2:$A$116,A14,Blocs!$E$2:$E$116,"Oui") -> 0 | E14: =COUNTIFS(Blocs!$A$2:$A$116,A14,Blocs!$F$2:$F$116,"<>À tester") -> 0 | F14: =COUNTIFS(Blocs!$A$2:$A$116,A14,Blocs!$F$2:$F$116,"Oui") -> 0
A15: Total | B15: =SUM(B4:B14) -> 115 | C15: =SUM(C4:C14) -> 19 | D15: =SUM(D4:D14) -> 18 | E15: =SUM(E4:E14) -> 21 | F15: =SUM(F4:F14) -> 20
